Traceback (most recent call last):
  File "/Users/mike/opt/anaconda3/envs/cs185c/lib/python3.11/site-packages/nbclient/client.py", line 782, in _async_poll_for_reply
    msg = await ensure_async(self.kc.shell_channel.get_msg(timeout=new_timeout))
          ^^^^^^^^^^^^^^^^^^^^^^^^^^^^^^^^^^^^^^^^^^^^^^^^^^^^^^^^^^^^^^^^^^^^^^
  File "/Users/mike/opt/anaconda3/envs/cs185c/lib/python3.11/site-packages/jupyter_core/utils/__init__.py", line 198, in ensure_async
    result = await obj
             ^^^^^^^^^
  File "/Users/mike/opt/anaconda3/envs/cs185c/lib/python3.11/site-packages/jupyter_client/channels.py", line 313, in get_msg
    raise Empty
_queue.Empty

During handling of the above exception, another exception occurred:

Traceback (most recent call last):
  File "/Users/mike/opt/anaconda3/envs/cs185c/lib/python3.11/site-packages/jupyter_cache/executors/utils.py", line 58, in single_nb_execution
    executenb(
  File "/Users/mike/opt/anaconda3/envs/cs185c/lib/python3.11/site-packages/nbclient/client.py", line 1314, in execute
    return NotebookClient(nb=nb, resources=resources, km=km, **kwargs).execute()
           ^^^^^^^^^^^^^^^^^^^^^^^^^^^^^^^^^^^^^^^^^^^^^^^^^^^^^^^^^^^^^^^^^^^^^
  File "/Users/mike/opt/anaconda3/envs/cs185c/lib/python3.11/site-packages/jupyter_core/utils/__init__.py", line 165, in wrapped
    return loop.run_until_complete(inner)
           ^^^^^^^^^^^^^^^^^^^^^^^^^^^^^^
  File "/Users/mike/opt/anaconda3/envs/cs185c/lib/python3.11/asyncio/base_events.py", line 654, in run_until_complete
    return future.result()
           ^^^^^^^^^^^^^^^
  File "/Users/mike/opt/anaconda3/envs/cs185c/lib/python3.11/site-packages/nbclient/client.py", line 709, in async_execute
    await self.async_execute_cell(
  File "/Users/mike/opt/anaconda3/envs/cs185c/lib/python3.11/site-packages/nbclient/client.py", line 1005, in async_execute_cell
    exec_reply = await self.task_poll_for_reply
                 ^^^^^^^^^^^^^^^^^^^^^^^^^^^^^^
  File "/Users/mike/opt/anaconda3/envs/cs185c/lib/python3.11/site-packages/nbclient/client.py", line 806, in _async_poll_for_reply
    error_on_timeout_execute_reply = await self._async_handle_timeout(timeout, cell)
                                     ^^^^^^^^^^^^^^^^^^^^^^^^^^^^^^^^^^^^^^^^^^^^^^^
  File "/Users/mike/opt/anaconda3/envs/cs185c/lib/python3.11/site-packages/nbclient/client.py", line 856, in _async_handle_timeout
    raise CellTimeoutError.error_from_timeout_and_cell(
nbclient.exceptions.CellTimeoutError: A cell timed out while it was being executed, after 30 seconds.
The message was: Cell execution timed out.
Here is a preview of the cell contents:
-------------------
depth = bathy
delR = np.array([ 10.00, 10.00, 10.00, 10.00, 10.00, 10.00, 10.00, 10.01,
                 10.03, 10.11, 10.32, 10.80, 11.76, 13.42, 16.04, 19.82, 24.85,
                 31.10, 38.42, 46.50, 55.00, 63.50, 71.58, 78.90, 85.15, 90.18,
                 93.96, 96.58, 98.25, 99.25,100.01,101.33,104.56,111.33,122.83,
                 139.09,158.94,180.83,203.55,226.50,249.50,272.50,295.50,318.50,
                 341.50,364.50,387.50,410.50,433.50,456.50,])
Z = np.cumsum(delR)
hFacC = hFac.create_hFacC_grid(depth, delR)
-------------------

